Traceback (most recent call last):
  File "/home/guangyaoyang/anaconda3/envs/gluon/lib/python3.6/urllib/request.py", line 1318, in do_open
    encode_chunked=req.has_header('Transfer-encoding'))
  File "/home/guangyaoyang/anaconda3/envs/gluon/lib/python3.6/http/client.py", line 1239, in request
    self._send_request(method, url, body, headers, encode_chunked)
  File "/home/guangyaoyang/anaconda3/envs/gluon/lib/python3.6/http/client.py", line 1285, in _send_request
    self.endheaders(body, encode_chunked=encode_chunked)
  File "/home/guangyaoyang/anaconda3/envs/gluon/lib/python3.6/http/client.py", line 1234, in endheaders
    self._send_output(message_body, encode_chunked=encode_chunked)
  File "/home/guangyaoyang/anaconda3/envs/gluon/lib/python3.6/http/client.py", line 1026, in _send_output
    self.send(msg)
  File "/home/guangyaoyang/anaconda3/envs/gluon/lib/python3.6/http/client.py", line 964, in send
    self.connect()
  File "/home/guangyaoyang/anaconda3/envs/gluon/lib/python3.6/http/client.py", line 1392, in connect
    super().connect()
  File "/home/guangyaoyang/anaconda3/envs/gluon/lib/python3.6/http/client.py", line 936, in connect
    (self.host,self.port), self.timeout, self.source_address)
  File "/home/guangyaoyang/anaconda3/envs/gluon/lib/python3.6/socket.py", line 724, in create_connection
    raise err
  File "/home/guangyaoyang/anaconda3/envs/gluon/lib/python3.6/socket.py", line 713, in create_connection
    sock.connect(sa)
TimeoutError: [Errno 110] Connection timed out

During handling of the above exception, another exception occurred:

Traceback (most recent call last):
  File "/home/guangyaoyang/anaconda3/envs/gluon/lib/python3.6/site-packages/visdom/server.py", line 693, in download_scripts
    data = opener.open(req).read()
  File "/home/guangyaoyang/anaconda3/envs/gluon/lib/python3.6/urllib/request.py", line 526, in open
    response = self._open(req, data)
  File "/home/guangyaoyang/anaconda3/envs/gluon/lib/python3.6/urllib/request.py", line 544, in _open
    '_open', req)
  File "/home/guangyaoyang/anaconda3/envs/gluon/lib/python3.6/urllib/request.py", line 504, in _call_chain
    result = func(*args)
  File "/home/guangyaoyang/anaconda3/envs/gluon/lib/python3.6/urllib/request.py", line 1361, in https_open
    context=self._context, check_hostname=self._check_hostname)
  File "/home/guangyaoyang/anaconda3/envs/gluon/lib/python3.6/urllib/request.py", line 1320, in do_open
    raise URLError(err)
urllib.error.URLError: <urlopen error [Errno 110] Connection timed out>

During handling of the above exception, another exception occurred:

Traceback (most recent call last):
  File "/home/guangyaoyang/anaconda3/envs/gluon/lib/python3.6/runpy.py", line 193, in _run_module_as_main
    "__main__", mod_spec)
  File "/home/guangyaoyang/anaconda3/envs/gluon/lib/python3.6/runpy.py", line 85, in _run_code
    exec(code, run_globals)
  File "/home/guangyaoyang/anaconda3/envs/gluon/lib/python3.6/site-packages/visdom/server.py", line 717, in <module>
    download_scripts()
  File "/home/guangyaoyang/anaconda3/envs/gluon/lib/python3.6/site-packages/visdom/server.py", line 697, in download_scripts
    logging.error('Error {} while downloading {}'.format(exc.code, key))
AttributeError: 'URLError' object has no attribute 'code'
Downloading scripts. It might take a while.
Traceback (most recent call last):
  File "/home/guangyaoyang/anaconda3/envs/gluon/lib/python3.6/urllib/request.py", line 1318, in do_open
    encode_chunked=req.has_header('Transfer-encoding'))
  File "/home/guangyaoyang/anaconda3/envs/gluon/lib/python3.6/http/client.py", line 1239, in request
    self._send_request(method, url, body, headers, encode_chunked)
  File "/home/guangyaoyang/anaconda3/envs/gluon/lib/python3.6/http/client.py", line 1285, in _send_request
    self.endheaders(body, encode_chunked=encode_chunked)
  File "/home/guangyaoyang/anaconda3/envs/gluon/lib/python3.6/http/client.py", line 1234, in endheaders
    self._send_output(message_body, encode_chunked=encode_chunked)
  File "/home/guangyaoyang/anaconda3/envs/gluon/lib/python3.6/http/client.py", line 1026, in _send_output
    self.send(msg)
  File "/home/guangyaoyang/anaconda3/envs/gluon/lib/python3.6/http/client.py", line 964, in send
    self.connect()
  File "/home/guangyaoyang/anaconda3/envs/gluon/lib/python3.6/http/client.py", line 1400, in connect
    server_hostname=server_hostname)
  File "/home/guangyaoyang/anaconda3/envs/gluon/lib/python3.6/ssl.py", line 407, in wrap_socket
    _context=self, _session=session)
  File "/home/guangyaoyang/anaconda3/envs/gluon/lib/python3.6/ssl.py", line 814, in __init__
    self.do_handshake()
  File "/home/guangyaoyang/anaconda3/envs/gluon/lib/python3.6/ssl.py", line 1068, in do_handshake
    self._sslobj.do_handshake()
  File "/home/guangyaoyang/anaconda3/envs/gluon/lib/python3.6/ssl.py", line 689, in do_handshake
    self._sslobj.do_handshake()
ConnectionResetError: [Errno 104] Connection reset by peer

During handling of the above exception, another exception occurred:

Traceback (most recent call last):
  File "/home/guangyaoyang/anaconda3/envs/gluon/lib/python3.6/site-packages/visdom/server.py", line 693, in download_scripts
    data = opener.open(req).read()
  File "/home/guangyaoyang/anaconda3/envs/gluon/lib/python3.6/urllib/request.py", line 526, in open
    response = self._open(req, data)
  File "/home/guangyaoyang/anaconda3/envs/gluon/lib/python3.6/urllib/request.py", line 544, in _open
    '_open', req)
  File "/home/guangyaoyang/anaconda3/envs/gluon/lib/python3.6/urllib/request.py", line 504, in _call_chain
    result = func(*args)
  File "/home/guangyaoyang/anaconda3/envs/gluon/lib/python3.6/urllib/request.py", line 1361, in https_open
    context=self._context, check_hostname=self._check_hostname)
  File "/home/guangyaoyang/anaconda3/envs/gluon/lib/python3.6/urllib/request.py", line 1320, in do_open
    raise URLError(err)
urllib.error.URLError: <urlopen error [Errno 104] Connection reset by peer>

During handling of the above exception, another exception occurred:

Traceback (most recent call last):
  File "/home/guangyaoyang/anaconda3/envs/gluon/lib/python3.6/runpy.py", line 193, in _run_module_as_main
    "__main__", mod_spec)
  File "/home/guangyaoyang/anaconda3/envs/gluon/lib/python3.6/runpy.py", line 85, in _run_code
    exec(code, run_globals)
  File "/home/guangyaoyang/anaconda3/envs/gluon/lib/python3.6/site-packages/visdom/server.py", line 717, in <module>
    download_scripts()
  File "/home/guangyaoyang/anaconda3/envs/gluon/lib/python3.6/site-packages/visdom/server.py", line 697, in download_scripts
    logging.error('Error {} while downloading {}'.format(exc.code, key))
AttributeError: 'URLError' object has no attribute 'code'
Downloading scripts. It might take a while.
